<?xml version="1.0"?>
<robot xmlns:xacro="http://www.ros.org/wiki/xacro" name="my_robot">

  <!-- ─── Properties ─────────────────────────────────────── -->
  <xacro:property name="base_length"  value="0.4"/>
  <xacro:property name="base_width"   value="0.3"/>
  <xacro:property name="base_height"  value="0.15"/>
  <xacro:property name="wheel_radius" value="0.075"/>
  <xacro:property name="wheel_width"  value="0.05"/>
  <xacro:property name="wheel_offset_y" value="0.175"/>

  <!-- ─── Base Link ──────────────────────────────────────── -->
  <link name="base_link"/>

  <link name="base_footprint"/>
  <joint name="base_footprint_joint" type="fixed">
    <parent link="base_footprint"/>
    <child  link="base_link"/>
    <origin xyz="0 0 ${wheel_radius}" rpy="0 0 0"/>
  </joint>

  <!-- Chassis -->
  <link name="chassis_link">
    <visual>
      <origin xyz="${base_length/2} 0 0" rpy="0 0 0"/>
      <geometry>
        <box size="${base_length} ${base_width} ${base_height}"/>
      </geometry>
      <material name="blue">
        <color rgba="0.2 0.4 0.8 1.0"/>
      </material>
    </visual>
    <collision>
      <origin xyz="${base_length/2} 0 0" rpy="0 0 0"/>
      <geometry>
        <box size="${base_length} ${base_width} ${base_height}"/>
      </geometry>
    </collision>
    <inertial>
      <mass value="2.0"/>
      <origin xyz="${base_length/2} 0 0"/>
      <inertia ixx="0.02" iyy="0.02" izz="0.02"
               ixy="0"    ixz="0"    iyz="0"/>
    </inertial>
  </link>
  <joint name="chassis_joint" type="fixed">
    <parent link="base_link"/>
    <child  link="chassis_link"/>
    <origin xyz="0 0 0" rpy="0 0 0"/>
  </joint>

  <!-- ─── Wheel Macro ────────────────────────────────────── -->
  <xacro:macro name="wheel" params="name y_reflect">
    <link name="${name}_wheel_link">
      <visual>
        <geometry>
          <cylinder radius="${wheel_radius}" length="${wheel_width}"/>
        </geometry>
        <material name="black">
          <color rgba="0.1 0.1 0.1 1.0"/>
        </material>
      </visual>
      <collision>
        <geometry>
          <cylinder radius="${wheel_radius}" length="${wheel_width}"/>
        </geometry>
      </collision>
      <inertial>
        <mass value="0.3"/>
        <inertia ixx="0.001" iyy="0.001" izz="0.001"
                 ixy="0"     ixz="0"     iyz="0"/>
      </inertial>
    </link>
    <joint name="${name}_wheel_joint" type="continuous">
      <parent link="base_link"/>
      <child  link="${name}_wheel_link"/>
      <origin xyz="0.1 ${y_reflect * wheel_offset_y} 0" rpy="${-pi/2} 0 0"/>
      <axis xyz="0 0 1"/>
    </joint>
  </xacro:macro>

  <!-- ─── Instantiate Wheels ─────────────────────────────── -->
  <xacro:wheel name="left"  y_reflect=" 1"/>
  <xacro:wheel name="right" y_reflect="-1"/>

  <!-- ─── Caster Wheel ───────────────────────────────────── -->
  <link name="caster_link">
    <visual>
      <geometry>
        <sphere radius="${wheel_radius/2}"/>
      </geometry>
      <material name="grey">
        <color rgba="0.6 0.6 0.6 1.0"/>
      </material>
    </visual>
    <collision>
      <geometry>
        <sphere radius="${wheel_radius/2}"/>
      </geometry>
    </collision>
    <inertial>
      <mass value="0.1"/>
      <inertia ixx="0.0001" iyy="0.0001" izz="0.0001"
               ixy="0"      ixz="0"      iyz="0"/>
    </inertial>
  </link>
  <joint name="caster_joint" type="fixed">
    <parent link="base_link"/>
    <child  link="caster_link"/>
    <origin xyz="0.3 0 ${-wheel_radius/2}" rpy="0 0 0"/>
  </joint>

</robot>