<?xml version="1.0"?>
<robot xmlns:xacro="http://www.ros.org/wiki/xacro" name="my_robot">

  <!-- ─── Properties ─────────────────────────────────────── -->
  <xacro:property name="base_length"  value="0.4"/>
  <xacro:property name="base_width"   value="0.3"/>
  <xacro:property name="base_height"  value="0.15"/>
  <xacro:property name="wheel_radius" value="0.075"/>
  <xacro:property name="wheel_width"  value="0.05"/>
  <xacro:property name="wheel_offset_y" value="0.175"/>

  <!-- ─── Base Link ──────────────────────────────────────── -->
  <link name="base_link"/>

  <link name="base_footprint"/>
  <joint name="base_footprint_joint" type="fixed">
    <parent link="base_footprint"/>
    <child  link="base_link"/>
    <origin xyz="0 0 ${wheel_radius}" rpy="0 0 0"/>
  </joint>

  <!-- Chassis -->
  <link name="chassis_link">
    <visual>
      <origin xyz="${base_length/2} 0 0" rpy="0 0 0"/>
      <geometry>
        <box size="${base_length} ${base_width} ${base_height}"/>
      </geometry>
      <material name="blue">
        <color rgba="0.2 0.4 0.8 1.0"/>
      </material>
    </visual>
    <collision>
      <origin xyz="${base_length/2} 0 0" rpy="0 0 0"/>
      <geometry>
        <box size="${base_length} ${base_width} ${base_height}"/>
      </geometry>
    </collision>
    <inertial>
      <mass value="2.0"/>
      <origin xyz="${base_length/2} 0 0"/>
      <inertia ixx="0.02" iyy="0.02" izz="0.02"
               ixy="0"    ixz="0"    iyz="0"/>
    </inertial>
  </link>
  <joint name="chassis_joint" type="fixed">
    <parent link="base_link"/>
    <child  link="chassis_link"/>
    <origin xyz="0 0 0" rpy="0 0 0"/>
  </joint>

  <!-- ─── Wheel Macro ────────────────────────────────────── -->
  <xacro:macro name="wheel" params="name y_reflect">
    <link name="${name}_wheel_link">
      <visual>
        <origin xyz="0 0 0" rpy="${pi/2} 0 0"/>
        <geometry>
          <cylinder radius="${wheel_radius}" length="${wheel_width}"/>
        </geometry>
        <material name="black">
          <color rgba="0.1 0.1 0.1 1.0"/>
        </material>
      </visual>
      <collision>
        <origin xyz="0 0 0" rpy="${pi/2} 0 0"/>
        <geometry>
          <cylinder radius="${wheel_radius}" length="${wheel_width}"/>
        </geometry>
      </collision>
      <inertial>
        <mass value="0.3"/>
        <inertia ixx="0.001" iyy="0.001" izz="0.001"
                ixy="0"     ixz="0"     iyz="0"/>
      </inertial>
    </link>
    <joint name="${name}_wheel_joint" type="continuous">
      <parent link="base_link"/>
      <child  link="${name}_wheel_link"/>
      <origin xyz="0.1 ${y_reflect * wheel_offset_y} 0" rpy="0 0 0"/>
      <axis xyz="0 1 0"/>
      <limit effort="10" velocity="10"/>
  </joint>
  </xacro:macro>

  <!-- ─── Instantiate Wheels ─────────────────────────────── -->
  <xacro:wheel name="left"  y_reflect=" 1"/>
  <xacro:wheel name="right" y_reflect="-1"/>

  <!-- ─── Caster Wheel ───────────────────────────────────── -->
  <link name="caster_link">
    <visual>
      <geometry>
        <sphere radius="${wheel_radius/2}"/>
      </geometry>
      <material name="grey">
        <color rgba="0.6 0.6 0.6 1.0"/>
      </material>
    </visual>
    <collision>
      <geometry>
        <sphere radius="${wheel_radius/2}"/>
      </geometry>
    </collision>
    <inertial>
      <mass value="0.1"/>
      <inertia ixx="0.0001" iyy="0.0001" izz="0.0001"
               ixy="0"      ixz="0"      iyz="0"/>
    </inertial>
  </link>
  <joint name="caster_joint" type="fixed">
    <parent link="base_link"/>
    <child  link="caster_link"/>
    <origin xyz="0.3 0 ${-wheel_radius/2}" rpy="0 0 0"/>
  </joint>

<!-- ─── Wheel Friction ─────────────────────────────────── -->
  <gazebo reference="left_wheel_link">
    <mu1>1.0</mu1>
    <mu2>1.0</mu2>
  </gazebo>

  <gazebo reference="right_wheel_link">
    <mu1>1.0</mu1>
    <mu2>1.0</mu2>
  </gazebo>

  <!-- ─── IMU ──────────────────────────────────────────────── -->
  <!-- Mounted at geometric center of chassis top surface       -->
  <!-- xyz = (base_length/2, 0, base_height/2) = (0.2, 0, 0.075) in chassis_link frame -->
  <link name="imu_link">
    <visual>
      <geometry>
        <box size="0.05 0.05 0.02"/>
      </geometry>
      <material name="red">
        <color rgba="0.8 0.1 0.1 1.0"/>
      </material>
    </visual>
    <inertial>
      <mass value="0.01"/>
      <inertia ixx="1e-6" ixy="0" ixz="0"
               iyy="1e-6" iyz="0" izz="1e-6"/>
    </inertial>
  </link>

  <joint name="imu_joint" type="fixed">
    <parent link="chassis_link"/>
    <child  link="imu_link"/>
    <origin xyz="${base_length/2} 0 ${base_height/2}" rpy="0 0 0"/>
  </joint>

  <!-- ─── Gazebo Diff Drive Plugin ──────────────────────────
       Built-in Gazebo plugin — no ros2_control needed.
       Subscribes to /cmd_vel and publishes /odom directly.
  ──────────────────────────────────────────────────────────── -->
  <gazebo>
    <plugin filename="gz-sim-diff-drive-system"
            name="gz::sim::systems::DiffDrive">
      <left_joint>left_wheel_joint</left_joint>
      <right_joint>right_wheel_joint</right_joint>
      <wheel_separation>0.35</wheel_separation>
      <wheel_radius>0.075</wheel_radius>
      <odom_publish_frequency>50</odom_publish_frequency>
      <topic>/model/my_robot/cmd_vel</topic>
      <odom_topic>odom</odom_topic>
      <frame_id>odom</frame_id>
      <child_frame_id>base_footprint</child_frame_id>
    </plugin>
  </gazebo>

</robot>